Traceback (most recent call last):
  File "/home/runner/.local/lib/python3.12/site-packages/jupyter_core/utils/__init__.py", line 154, in wrapped
    asyncio.get_running_loop()
RuntimeError: no running event loop

During handling of the above exception, another exception occurred:

Traceback (most recent call last):
  File "/home/runner/.local/lib/python3.12/site-packages/jupyter_cache/executors/utils.py", line 58, in single_nb_execution
    executenb(
  File "/home/runner/.local/lib/python3.12/site-packages/nbclient/client.py", line 1319, in execute
    return NotebookClient(nb=nb, resources=resources, km=km, **kwargs).execute()
           ^^^^^^^^^^^^^^^^^^^^^^^^^^^^^^^^^^^^^^^^^^^^^^^^^^^^^^^^^^^^^^^^^^^^^
  File "/home/runner/.local/lib/python3.12/site-packages/jupyter_core/utils/__init__.py", line 158, in wrapped
    return loop.run_until_complete(inner)
           ^^^^^^^^^^^^^^^^^^^^^^^^^^^^^^
  File "/usr/lib/python3.12/asyncio/base_events.py", line 687, in run_until_complete
    return future.result()
           ^^^^^^^^^^^^^^^
  File "/home/runner/.local/lib/python3.12/site-packages/nbclient/client.py", line 709, in async_execute
    await self.async_execute_cell(
  File "/home/runner/.local/lib/python3.12/site-packages/nbclient/client.py", line 1062, in async_execute_cell
    await self._check_raise_for_error(cell, cell_index, exec_reply)
  File "/home/runner/.local/lib/python3.12/site-packages/nbclient/client.py", line 918, in _check_raise_for_error
    raise CellExecutionError.from_cell_and_msg(cell, exec_reply_content)
nbclient.exceptions.CellExecutionError: An error occurred while executing the following cell:
------------------
pcalc.calculate()
------------------


[31m---------------------------------------------------------------------------[39m
[31mAttributeError[39m                            Traceback (most recent call last)
[36mCell[39m[36m [39m[32mIn[6][39m[32m, line 1[39m
[32m----> [39m[32m1[39m [43mpcalc[49m[43m.[49m[43mcalculate[49m[43m([49m[43m)[49m

[36mFile [39m[32m~/.local/lib/python3.12/site-packages/qse/calc/pulser.py:174[39m, in [36mPulser.calculate[39m[34m(self, progress)[39m
[32m    171[39m [38;5;28;01mif[39;00m [38;5;28mself[39m.wtimes:
[32m    172[39m     t1 = time()
[32m--> [39m[32m174[39m [38;5;28mself[39m.results = [38;5;28;43mself[39;49m[43m.[49m[43msim[49m[43m.[49m[43mrun[49m(progress_bar=progress)
[32m    176[39m final_state = [38;5;28mself[39m.results.get_final_state()
[32m    177[39m [38;5;28mself[39m.statevector = qutip.core.dimensions.to_tensor_rep(final_state).flatten()

[31mAttributeError[39m: 'NoneType' object has no attribute 'run'

